<?xml version="1.0" ?>
<robot name="caddy_ai2" xmlns:xacro="http://www.ros.org/wiki/xacro">

<xacro:include filename="$(find caddy_ai2_description)/urdf/materials.xacro" />
<xacro:include filename="$(find caddy_ai2_description)/urdf/caddy_ai2.trans" />
<xacro:include filename="$(find caddy_ai2_description)/urdf/caddy_ai2.gazebo" />
<link name="base_link">
  <inertial>
    <origin xyz="-0.37394134652960426 0.04474377035954571 0.578955145397471" rpy="0 0 0"/>
    <mass value="6911.347233417728"/>
    <inertia ixx="1013.115849" iyy="3529.517774" izz="3990.17869" ixy="237.674052" iyz="-86.909623" ixz="271.442423"/>
  </inertial>
  <visual>
    <origin xyz="0 0 0" rpy="0 0 0"/>
    <geometry>
      <mesh filename="package://caddy_ai2_description/meshes/base_link.stl" scale="0.001 0.001 0.001"/>
    </geometry>
    <material name="silver"/>
  </visual>
  <collision>
    <origin xyz="0 0 0" rpy="0 0 0"/>
    <geometry>
      <mesh filename="package://caddy_ai2_description/meshes/base_link.stl" scale="0.001 0.001 0.001"/>
    </geometry>
  </collision>
</link>

<link name="steering_hub_left_1">
  <inertial>
    <origin xyz="0.04503654747079244 -1.5755382293813902e-06 -0.06500000000000006" rpy="0 0 0"/>
    <mass value="4.494220600265263"/>
    <inertia ixx="0.01341" iyy="0.01229" izz="0.008238" ixy="0.0" iyz="0.0" ixz="-0.0"/>
  </inertial>
  <visual>
    <origin xyz="-0.825 -0.33 -0.3" rpy="0 0 0"/>
    <geometry>
      <mesh filename="package://caddy_ai2_description/meshes/steering_hub_left_1.stl" scale="0.001 0.001 0.001"/>
    </geometry>
    <material name="silver"/>
  </visual>
  <collision>
    <origin xyz="-0.825 -0.33 -0.3" rpy="0 0 0"/>
    <geometry>
      <mesh filename="package://caddy_ai2_description/meshes/steering_hub_left_1.stl" scale="0.001 0.001 0.001"/>
    </geometry>
  </collision>
</link>

<link name="steering_hub_right_1">
  <inertial>
    <origin xyz="0.045036547470792665 -1.5755382292148568e-06 -0.06500000000000006" rpy="0 0 0"/>
    <mass value="4.494220600265263"/>
    <inertia ixx="0.01341" iyy="0.01229" izz="0.008238" ixy="0.0" iyz="0.0" ixz="0.0"/>
  </inertial>
  <visual>
    <origin xyz="-0.825 0.33 -0.3" rpy="0 0 0"/>
    <geometry>
      <mesh filename="package://caddy_ai2_description/meshes/steering_hub_right_1.stl" scale="0.001 0.001 0.001"/>
    </geometry>
    <material name="silver"/>
  </visual>
  <collision>
    <origin xyz="-0.825 0.33 -0.3" rpy="0 0 0"/>
    <geometry>
      <mesh filename="package://caddy_ai2_description/meshes/steering_hub_right_1.stl" scale="0.001 0.001 0.001"/>
    </geometry>
  </collision>
</link>

<link name="wheel_front_right_1">
  <inertial>
    <origin xyz="0.1000001611093495 3.306197996488791e-07 5.551115123125783e-17" rpy="0 0 0"/>
    <mass value="268.03659227457297"/>
    <inertia ixx="7.294149" iyy="4.517093" izz="4.517093" ixy="0.0" iyz="-0.0" ixz="0.0"/>
  </inertial>
  <visual>
    <origin xyz="-0.898058 0.330002 -0.235" rpy="0 0 0"/>
    <geometry>
      <mesh filename="package://caddy_ai2_description/meshes/wheel_front_right_1.stl" scale="0.001 0.001 0.001"/>
    </geometry>
    <material name="silver"/>
  </visual>
  <collision>
    <origin xyz="-0.898058 0.330002 -0.235" rpy="0 0 0"/>
    <geometry>
      <mesh filename="package://caddy_ai2_description/meshes/wheel_front_right_1.stl" scale="0.001 0.001 0.001"/>
    </geometry>
  </collision>
</link>

<link name="wheel_front_left_1">
  <inertial>
    <origin xyz="0.10000016110934795 3.306197997599014e-07 5.551115123125783e-17" rpy="0 0 0"/>
    <mass value="268.03659227457297"/>
    <inertia ixx="7.294149" iyy="4.517093" izz="4.517093" ixy="0.0" iyz="-0.0" ixz="0.0"/>
  </inertial>
  <visual>
    <origin xyz="-0.898058 -0.329998 -0.235" rpy="0 0 0"/>
    <geometry>
      <mesh filename="package://caddy_ai2_description/meshes/wheel_front_left_1.stl" scale="0.001 0.001 0.001"/>
    </geometry>
    <material name="silver"/>
  </visual>
  <collision>
    <origin xyz="-0.898058 -0.329998 -0.235" rpy="0 0 0"/>
    <geometry>
      <mesh filename="package://caddy_ai2_description/meshes/wheel_front_left_1.stl" scale="0.001 0.001 0.001"/>
    </geometry>
  </collision>
</link>

<link name="wheel_rear_right_1">
  <inertial>
    <origin xyz="2.2948702271818888e-08 -0.10000000305175799 2.0302066416899578e-09" rpy="0 0 0"/>
    <mass value="268.03659227457297"/>
    <inertia ixx="4.517093" iyy="7.294149" izz="4.517093" ixy="0.0" iyz="-0.0" ixz="0.0"/>
  </inertial>
  <visual>
    <origin xyz="0.825 0.4018 -0.235" rpy="0 0 0"/>
    <geometry>
      <mesh filename="package://caddy_ai2_description/meshes/wheel_rear_right_1.stl" scale="0.001 0.001 0.001"/>
    </geometry>
    <material name="silver"/>
  </visual>
  <collision>
    <origin xyz="0.825 0.4018 -0.235" rpy="0 0 0"/>
    <geometry>
      <mesh filename="package://caddy_ai2_description/meshes/wheel_rear_right_1.stl" scale="0.001 0.001 0.001"/>
    </geometry>
  </collision>
</link>

<link name="wheel_rear_left_1">
  <inertial>
    <origin xyz="2.2948702271818888e-08 0.10000000305175755 2.0302066416899578e-09" rpy="0 0 0"/>
    <mass value="268.03659227457297"/>
    <inertia ixx="4.517093" iyy="7.294149" izz="4.517093" ixy="0.0" iyz="0.0" ixz="-0.0"/>
  </inertial>
  <visual>
    <origin xyz="0.825 -0.4018 -0.235" rpy="0 0 0"/>
    <geometry>
      <mesh filename="package://caddy_ai2_description/meshes/wheel_rear_left_1.stl" scale="0.001 0.001 0.001"/>
    </geometry>
    <material name="silver"/>
  </visual>
  <collision>
    <origin xyz="0.825 -0.4018 -0.235" rpy="0 0 0"/>
    <geometry>
      <mesh filename="package://caddy_ai2_description/meshes/wheel_rear_left_1.stl" scale="0.001 0.001 0.001"/>
    </geometry>
  </collision>
</link>

<link name="SICK_LMS291_1">
  <inertial>
    <origin xyz="0.07087581656184416 1.7016769843495403e-06 -0.24450398457225875" rpy="0 0 0"/>
    <mass value="29.182325361169905"/>
    <inertia ixx="0.137412" iyy="0.137225" izz="0.100203" ixy="3e-06" iyz="3e-06" ixz="-0.005719"/>
  </inertial>
  <visual>
    <origin xyz="-0.990124 -0.0 -0.505" rpy="0 0 0"/>
    <geometry>
      <mesh filename="package://caddy_ai2_description/meshes/SICK_LMS291_1.stl" scale="0.001 0.001 0.001"/>
    </geometry>
    <material name="silver"/>
  </visual>
  <collision>
    <origin xyz="-0.990124 -0.0 -0.505" rpy="0 0 0"/>
    <geometry>
      <mesh filename="package://caddy_ai2_description/meshes/SICK_LMS291_1.stl" scale="0.001 0.001 0.001"/>
    </geometry>
  </collision>
</link>

<joint name="steer_left_joint" type="revolute">
  <origin xyz="0.825 0.33 0.3" rpy="0 0 0"/>
  <parent link="base_link"/>
  <child link="steering_hub_left_1"/>
  <axis xyz="0.0 0.0 1.0"/>
  <limit upper="0.785398" lower="-0.785398" effort="100" velocity="100"/>
</joint>

<joint name="steer_right_joint" type="revolute">
  <origin xyz="0.825 -0.33 0.3" rpy="0 0 0"/>
  <parent link="base_link"/>
  <child link="steering_hub_right_1"/>
  <axis xyz="0.0 0.0 1.0"/>
  <limit upper="0.785398" lower="-0.785398" effort="100" velocity="100"/>
</joint>

<joint name="front_right_joint" type="continuous">
  <origin xyz="0.073058 -2e-06 -0.065" rpy="0 0 0"/>
  <parent link="steering_hub_right_1"/>
  <child link="wheel_front_right_1"/>
  <axis xyz="1.0 -0.0 0.0"/>
</joint>

<joint name="front_left_joint" type="continuous">
  <origin xyz="0.073058 -2e-06 -0.065" rpy="0 0 0"/>
  <parent link="steering_hub_left_1"/>
  <child link="wheel_front_left_1"/>
  <axis xyz="1.0 0.0 0.0"/>
</joint>

<joint name="rear_right_joint" type="continuous">
  <origin xyz="-0.825 -0.4018 0.235" rpy="0 0 0"/>
  <parent link="base_link"/>
  <child link="wheel_rear_right_1"/>
  <axis xyz="0.0 -1.0 0.0"/>
</joint>

<joint name="rear_left_joint" type="continuous">
  <origin xyz="-0.825 0.4018 0.235" rpy="0 0 0"/>
  <parent link="base_link"/>
  <child link="wheel_rear_left_1"/>
  <axis xyz="-0.0 1.0 0.0"/>
</joint>

<joint name="lidar_joint" type="fixed">
  <origin xyz="0.990124 0.0 0.505" rpy="0 0 0"/>
  <parent link="base_link"/>
  <child link="SICK_LMS291_1"/>
</joint>

</robot>
